Workbook

Sheet Sheet1
A1: uchar | C1: Schematic Sheet | D1: REF Des | E1: REF Des | F1: Zero = | G1: One = | H1: Description | I1: Note | J1: I/O | K1: Chip Select Group (for each channel) | L1: GPIO Expansion Chip I/O port (pin) name
A2: pCUT :1, | B2: =CONCATENATE("//* 0 = ",F2," <BR> 1 = ",G2," <BR> Description: ",H2," <BR> I/O: ",J2," <BR> Chip Select Group: ",K2," <BR> GPIO Port (Pin) Name: ",L2," <BR> Schematic Sheet of Interest: ",C2," <BR> Reference Designators of Interest: ", CONCATENATE(D2,", ",E2),IF(I2<>"",CONCATENATE(" <BR> Note: ",I2),"")) -> //* 0 = Output level CUT mode <BR> 1 = Output level not CUTting <BR> Description: Gain Mode Switch (Cut), Front Panel <BR> I/O: Input (Active Low) <BR> Chip Select Group: CS_A <BR> GPIO Port (Pin) Name: P0 <BR> Schematic Sheet of Interest: Front Panel, SPI GPIO input sheet <BR> Reference Designators of Interest: S1, <BR> Note: Gain mode OUT is calculated when neither Cut or Boost is active, and should set Output Level seven relay ladder range and output relay 1 for 0dB | C2: Front Panel, SPI GPIO input sheet | D2: S1 | F2: Output level CUT mode | G2: Output level not CUTting | H2: Gain Mode Switch (Cut), Front Panel | I2: Gain mode OUT is calculated when neither Cut or Boost is active, and should set Output Level seven relay ladder range and output relay 1 for 0dB | J2: =VLOOKUP(LEFT(TRIM(A2),1),$U$2:$V$5,2,FALSE) -> Input (Active Low) | K2: CS_A | L2: P0 | U2: p | V2: Input (Active Low)
A3: pBOOST :1, | B3: =CONCATENATE("//* 0 = ",F3," <BR> 1 = ",G3," <BR> Description: ",H3," <BR> I/O: ",J3," <BR> Chip Select Group: ",K3," <BR> GPIO Port (Pin) Name: ",L3," <BR> Schematic Sheet of Interest: ",C3," <BR> Reference Designators of Interest: ", CONCATENATE(D3,", ",E3),IF(I3<>"",CONCATENATE(" <BR> Note: ",I3),"")) -> //* 0 = Output level BOOST mode <BR> 1 = Output level not BOOSTing <BR> Description: Gain Mode Switch (Boost), Front Panel <BR> I/O: Input (Active Low) <BR> Chip Select Group: CS_A <BR> GPIO Port (Pin) Name: P1 <BR> Schematic Sheet of Interest: Front Panel, SPI GPIO input sheet <BR> Reference Designators of Interest: S1, <BR> Note: Gain mode OUT is calculated when neither Cut or Boost is active, and should set Output Level seven relay ladder range and output relay 1 for 0dB | C3: Front Panel, SPI GPIO input sheet | D3: S1 | F3: Output level BOOST mode | G3: Output level not BOOSTing | H3: Gain Mode Switch (Boost), Front Panel | I3: Gain mode OUT is calculated when neither Cut or Boost is active, and should set Output Level seven relay ladder range and output relay 1 for 0dB | J3: =VLOOKUP(LEFT(TRIM(A3),1),$U$2:$V$5,2,FALSE) -> Input (Active Low) | K3: CS_A | L3: P1 | U3: b | V3: Input (Active High)
A4: bLOADING_A0 :1, | B4: =CONCATENATE("//* 0 = ",F4," <BR> 1 = ",G4," <BR> Description: ",H4," <BR> I/O: ",J4," <BR> Chip Select Group: ",K4," <BR> GPIO Port (Pin) Name: ",L4," <BR> Schematic Sheet of Interest: ",C4," <BR> Reference Designators of Interest: ", CONCATENATE(D4,", ",E4),IF(I4<>"",CONCATENATE(" <BR> Note: ",I4),"")) -> //* 0 = Binary group (4-bits) not active <BR> 1 = Binary group (4-bits) active <BR> Description: Loading Knob bit 0 <BR> I/O: Input (Active High) <BR> Chip Select Group: CS_A <BR> GPIO Port (Pin) Name: P2 <BR> Schematic Sheet of Interest: Front Panel, SPI GPIO input sheet <BR> Reference Designators of Interest: SW3, <BR> Note: Twelve positions is represented by these four bits (Loading Knob[3:0]) with zero base reference from 0 to 11 in binary count | C4: Front Panel, SPI GPIO input sheet | D4: SW3 | F4: Binary group (4-bits) not active | G4: Binary group (4-bits) active | H4: Loading Knob bit 0 | I4: Twelve positions is represented by these four bits (Loading Knob[3:0]) with zero base reference from 0 to 11 in binary count | J4: =VLOOKUP(LEFT(TRIM(A4),1),$U$2:$V$5,2,FALSE) -> Input (Active High) | K4: CS_A | L4: P2 | U4: q | V4: Output (Acvtive Low)
A5: bLOADING_A1 :1, | B5: =CONCATENATE("//* 0 = ",F5," <BR> 1 = ",G5," <BR> Description: ",H5," <BR> I/O: ",J5," <BR> Chip Select Group: ",K5," <BR> GPIO Port (Pin) Name: ",L5," <BR> Schematic Sheet of Interest: ",C5," <BR> Reference Designators of Interest: ", CONCATENATE(D5,", ",E5),IF(I5<>"",CONCATENATE(" <BR> Note: ",I5),"")) -> //* 0 = Binary group (4-bits) not active <BR> 1 = Binary group (4-bits) active <BR> Description: Loading Knob bit 1 <BR> I/O: Input (Active High) <BR> Chip Select Group: CS_A <BR> GPIO Port (Pin) Name: P3 <BR> Schematic Sheet of Interest: Front Panel, SPI GPIO input sheet <BR> Reference Designators of Interest: SW3, <BR> Note: Twelve positions is represented by these four bits (Loading Knob[3:0]) with zero base reference from 0 to 11 in binary count | C5: Front Panel, SPI GPIO input sheet | D5: SW3 | F5: Binary group (4-bits) not active | G5: Binary group (4-bits) active | H5: Loading Knob bit 1 | I5: Twelve positions is represented by these four bits (Loading Knob[3:0]) with zero base reference from 0 to 11 in binary count | J5: =VLOOKUP(LEFT(TRIM(A5),1),$U$2:$V$5,2,FALSE) -> Input (Active High) | K5: CS_A | L5: P3 | U5: d | V5: Output (Active High)
A6: bLOADING_A2 :1, | B6: =CONCATENATE("//* 0 = ",F6," <BR> 1 = ",G6," <BR> Description: ",H6," <BR> I/O: ",J6," <BR> Chip Select Group: ",K6," <BR> GPIO Port (Pin) Name: ",L6," <BR> Schematic Sheet of Interest: ",C6," <BR> Reference Designators of Interest: ", CONCATENATE(D6,", ",E6),IF(I6<>"",CONCATENATE(" <BR> Note: ",I6),"")) -> //* 0 = Binary group (4-bits) not active <BR> 1 = Binary group (4-bits) active <BR> Description: Loading Knob bit 2 <BR> I/O: Input (Active High) <BR> Chip Select Group: CS_A <BR> GPIO Port (Pin) Name: P4 <BR> Schematic Sheet of Interest: Front Panel, SPI GPIO input sheet <BR> Reference Designators of Interest: SW3, <BR> Note: Twelve positions is represented by these four bits (Loading Knob[3:0]) with zero base reference from 0 to 11 in binary count | C6: Front Panel, SPI GPIO input sheet | D6: SW3 | F6: Binary group (4-bits) not active | G6: Binary group (4-bits) active | H6: Loading Knob bit 2 | I6: Twelve positions is represented by these four bits (Loading Knob[3:0]) with zero base reference from 0 to 11 in binary count | J6: =VLOOKUP(LEFT(TRIM(A6),1),$U$2:$V$5,2,FALSE) -> Input (Active High) | K6: CS_A | L6: P4
A7: bLOADING_A3 :1, | B7: =CONCATENATE("//* 0 = ",F7," <BR> 1 = ",G7," <BR> Description: ",H7," <BR> I/O: ",J7," <BR> Chip Select Group: ",K7," <BR> GPIO Port (Pin) Name: ",L7," <BR> Schematic Sheet of Interest: ",C7," <BR> Reference Designators of Interest: ", CONCATENATE(D7,", ",E7),IF(I7<>"",CONCATENATE(" <BR> Note: ",I7),"")) -> //* 0 = Binary group (4-bits) not active <BR> 1 = Binary group (4-bits) active <BR> Description: Loading Knob bit 3 <BR> I/O: Input (Active High) <BR> Chip Select Group: CS_A <BR> GPIO Port (Pin) Name: P5 <BR> Schematic Sheet of Interest: Front Panel, SPI GPIO input sheet <BR> Reference Designators of Interest: SW3, <BR> Note: Twelve positions is represented by these four bits (Loading Knob[3:0]) with zero base reference from 0 to 11 in binary count | C7: Front Panel, SPI GPIO input sheet | D7: SW3 | F7: Binary group (4-bits) not active | G7: Binary group (4-bits) active | H7: Loading Knob bit 3 | I7: Twelve positions is represented by these four bits (Loading Knob[3:0]) with zero base reference from 0 to 11 in binary count | J7: =VLOOKUP(LEFT(TRIM(A7),1),$U$2:$V$5,2,FALSE) -> Input (Active High) | K7: CS_A | L7: P5
A8: pXFORMER_A0 :1, | B8: =CONCATENATE("//* 0 = ",F8," <BR> 1 = ",G8," <BR> Description: ",H8," <BR> I/O: ",J8," <BR> Chip Select Group: ",K8," <BR> GPIO Port (Pin) Name: ",L8," <BR> Schematic Sheet of Interest: ",C8," <BR> Reference Designators of Interest: ", CONCATENATE(D8,", ",E8),IF(I8<>"",CONCATENATE(" <BR> Note: ",I8),"")) -> //* 0 = Binary group (2-bits) active <BR> 1 = Binary group (2-bits) not active <BR> Description: Transformer Mode Knob bit 0 <BR> I/O: Input (Active Low) <BR> Chip Select Group: CS_A <BR> GPIO Port (Pin) Name: P6 <BR> Schematic Sheet of Interest: Front Panel, SPI GPIO input sheet <BR> Reference Designators of Interest: SW2, <BR> Note: Transformer mode is simple binary mode 0 through 2: 0 is Transformer OUT, Modes 1 and 2 are implemented in algorithms herein | C8: Front Panel, SPI GPIO input sheet | D8: SW2 | F8: Binary group (2-bits) active | G8: Binary group (2-bits) not active | H8: Transformer Mode Knob bit 0 | I8: Transformer mode is simple binary mode 0 through 2: 0 is Transformer OUT, Modes 1 and 2 are implemented in algorithms herein | J8: =VLOOKUP(LEFT(TRIM(A8),1),$U$2:$V$5,2,FALSE) -> Input (Active Low) | K8: CS_A | L8: P6
A9: pXFORMER_A1 :1; | B9: =CONCATENATE("//* 0 = ",F9," <BR> 1 = ",G9," <BR> Description: ",H9," <BR> I/O: ",J9," <BR> Chip Select Group: ",K9," <BR> GPIO Port (Pin) Name: ",L9," <BR> Schematic Sheet of Interest: ",C9," <BR> Reference Designators of Interest: ", CONCATENATE(D9,", ",E9),IF(I9<>"",CONCATENATE(" <BR> Note: ",I9),"")) -> //* 0 = Binary group (2-bits) active <BR> 1 = Binary group (2-bits) not active <BR> Description: Transformer Mode Knob bit 1 <BR> I/O: Input (Active Low) <BR> Chip Select Group: CS_A <BR> GPIO Port (Pin) Name: P7 <BR> Schematic Sheet of Interest: Front Panel, SPI GPIO input sheet <BR> Reference Designators of Interest: SW2, <BR> Note: Transformer mode is simple binary mode 0 through 2: 0 is Transformer OUT, Modes 1 and 2 are implemented in algorithms herein | C9: Front Panel, SPI GPIO input sheet | D9: SW2 | F9: Binary group (2-bits) active | G9: Binary group (2-bits) not active | H9: Transformer Mode Knob bit 1 | I9: Transformer mode is simple binary mode 0 through 2: 0 is Transformer OUT, Modes 1 and 2 are implemented in algorithms herein | J9: =VLOOKUP(LEFT(TRIM(A9),1),$U$2:$V$5,2,FALSE) -> Input (Active Low) | K9: CS_A | L9: P7
A11: #define BYTE_INDEX_OUTLEVEL_KNOB 1
A12: #define BYTE_INDEX_FILTER_KNOB 1
A13: #define MASK_OUTLEVEL_KNOB 0b00111100
A14: #define SHIFT_OUTLEVEL_KNOB 2
A15: #define MASK_FILTER_KNOB 0b11000000
A16: #define SHIFT_FILTER_KNOB 6
A18: uchar
A19: pFILTER_A0 :1, | B19: =CONCATENATE("//* 0 = ",F19," <BR> 1 = ",G19," <BR> Description: ",H19," <BR> I/O: ",J19," <BR> Chip Select Group: ",K19," <BR> GPIO Port (Pin) Name: ",L19," <BR> Schematic Sheet of Interest: ",C19," <BR> Reference Designators of Interest: ", CONCATENATE(D19,", ",E19),IF(I19<>"",CONCATENATE(" <BR> Note: ",I19),"")) -> //* 0 = Binary group (2-bits) active <BR> 1 = Binary group (2-bits) not active <BR> Description: Filter Mode Knob bit 0 <BR> I/O: Input (Active Low) <BR> Chip Select Group: CS_A <BR> GPIO Port (Pin) Name: P8 <BR> Schematic Sheet of Interest: Front Panel, SPI GPIO input sheet <BR> Reference Designators of Interest: SW1, <BR> Note: Filter mode is simple binary mode 0 through 3: 0 is Filter OUT, Mode 1: Hi, Mode 2 Low, Mode 3 Duo | C19: Front Panel, SPI GPIO input sheet | D19: SW1 | F19: Binary group (2-bits) active | G19: Binary group (2-bits) not active | H19: Filter Mode Knob bit 0 | I19: Filter mode is simple binary mode 0 through 3: 0 is Filter OUT, Mode 1: Hi, Mode 2 Low, Mode 3 Duo | J19: =VLOOKUP(LEFT(TRIM(A19),1),$U$2:$V$5,2,FALSE) -> Input (Active Low) | K19: CS_A | L19: P8
A20: pFILTER_A1 :1, | B20: =CONCATENATE("//* 0 = ",F20," <BR> 1 = ",G20," <BR> Description: ",H20," <BR> I/O: ",J20," <BR> Chip Select Group: ",K20," <BR> GPIO Port (Pin) Name: ",L20," <BR> Schematic Sheet of Interest: ",C20," <BR> Reference Designators of Interest: ", CONCATENATE(D20,", ",E20),IF(I20<>"",CONCATENATE(" <BR> Note: ",I20),"")) -> //* 0 = Binary group (2-bits) active <BR> 1 = Binary group (2-bits) not active <BR> Description: Filter Mode Knob bit 1 <BR> I/O: Input (Active Low) <BR> Chip Select Group: CS_A <BR> GPIO Port (Pin) Name: P9 <BR> Schematic Sheet of Interest: Front Panel, SPI GPIO input sheet <BR> Reference Designators of Interest: SW1, <BR> Note: Filter mode is simple binary mode 0 through 3: 0 is Filter OUT, Mode 1: Hi, Mode 2 Low, Mode 3 Duo | C20: Front Panel, SPI GPIO input sheet | D20: SW1 | F20: Binary group (2-bits) active | G20: Binary group (2-bits) not active | H20: Filter Mode Knob bit 1 | I20: Filter mode is simple binary mode 0 through 3: 0 is Filter OUT, Mode 1: Hi, Mode 2 Low, Mode 3 Duo | J20: =VLOOKUP(LEFT(TRIM(A20),1),$U$2:$V$5,2,FALSE) -> Input (Active Low) | K20: CS_A | L20: P9
A21: bOUTLEVEL_A0 :1, | B21: =CONCATENATE("//* 0 = ",F21," <BR> 1 = ",G21," <BR> Description: ",H21," <BR> I/O: ",J21," <BR> Chip Select Group: ",K21," <BR> GPIO Port (Pin) Name: ",L21," <BR> Schematic Sheet of Interest: ",C21," <BR> Reference Designators of Interest: ", CONCATENATE(D21,", ",E21),IF(I21<>"",CONCATENATE(" <BR> Note: ",I21),"")) -> //* 0 = Binary group (4-bits) not active <BR> 1 = Binary group (4-bits) active <BR> Description: Output Level Gain Knob bit 0 <BR> I/O: Input (Active High) <BR> Chip Select Group: CS_A <BR> GPIO Port (Pin) Name: P10 <BR> Schematic Sheet of Interest: Front Panel, SPI GPIO input sheet <BR> Reference Designators of Interest: SW4, <BR> Note: Twelve positions is represented by these four bits (Output Level Knob[3:0]) with zero base reference from 0 to 11 in binary count | C21: Front Panel, SPI GPIO input sheet | D21: SW4 | F21: Binary group (4-bits) not active | G21: Binary group (4-bits) active | H21: Output Level Gain Knob bit 0 | I21: Twelve positions is represented by these four bits (Output Level Knob[3:0]) with zero base reference from 0 to 11 in binary count | J21: =VLOOKUP(LEFT(TRIM(A21),1),$U$2:$V$5,2,FALSE) -> Input (Active High) | K21: CS_A | L21: P10
A22: bOUTLEVEL_A1 :1, | B22: =CONCATENATE("//* 0 = ",F22," <BR> 1 = ",G22," <BR> Description: ",H22," <BR> I/O: ",J22," <BR> Chip Select Group: ",K22," <BR> GPIO Port (Pin) Name: ",L22," <BR> Schematic Sheet of Interest: ",C22," <BR> Reference Designators of Interest: ", CONCATENATE(D22,", ",E22),IF(I22<>"",CONCATENATE(" <BR> Note: ",I22),"")) -> //* 0 = Binary group (4-bits) not active <BR> 1 = Binary group (4-bits) active <BR> Description: Output Level Gain Knob bit 1 <BR> I/O: Input (Active High) <BR> Chip Select Group: CS_A <BR> GPIO Port (Pin) Name: P11 <BR> Schematic Sheet of Interest: Front Panel, SPI GPIO input sheet <BR> Reference Designators of Interest: SW4, <BR> Note: Twelve positions is represented by these four bits (Output Level Knob[3:0]) with zero base reference from 0 to 11 in binary count | C22: Front Panel, SPI GPIO input sheet | D22: SW4 | F22: Binary group (4-bits) not active | G22: Binary group (4-bits) active | H22: Output Level Gain Knob bit 1 | I22: Twelve positions is represented by these four bits (Output Level Knob[3:0]) with zero base reference from 0 to 11 in binary count | J22: =VLOOKUP(LEFT(TRIM(A22),1),$U$2:$V$5,2,FALSE) -> Input (Active High) | K22: CS_A | L22: P11
A23: bOUTLEVEL_A2 :1, | B23: =CONCATENATE("//* 0 = ",F23," <BR> 1 = ",G23," <BR> Description: ",H23," <BR> I/O: ",J23," <BR> Chip Select Group: ",K23," <BR> GPIO Port (Pin) Name: ",L23," <BR> Schematic Sheet of Interest: ",C23," <BR> Reference Designators of Interest: ", CONCATENATE(D23,", ",E23),IF(I23<>"",CONCATENATE(" <BR> Note: ",I23),"")) -> //* 0 = Binary group (4-bits) not active <BR> 1 = Binary group (4-bits) active <BR> Description: Output Level Gain Knob bit 2 <BR> I/O: Input (Active High) <BR> Chip Select Group: CS_A <BR> GPIO Port (Pin) Name: P12 <BR> Schematic Sheet of Interest: Front Panel, SPI GPIO input sheet <BR> Reference Designators of Interest: SW4, <BR> Note: Twelve positions is represented by these four bits (Output Level Knob[3:0]) with zero base reference from 0 to 11 in binary count | C23: Front Panel, SPI GPIO input sheet | D23: SW4 | F23: Binary group (4-bits) not active | G23: Binary group (4-bits) active | H23: Output Level Gain Knob bit 2 | I23: Twelve positions is represented by these four bits (Output Level Knob[3:0]) with zero base reference from 0 to 11 in binary count | J23: =VLOOKUP(LEFT(TRIM(A23),1),$U$2:$V$5,2,FALSE) -> Input (Active High) | K23: CS_A | L23: P12
A24: bOUTLEVEL_A3 :1, | B24: =CONCATENATE("//* 0 = ",F24," <BR> 1 = ",G24," <BR> Description: ",H24," <BR> I/O: ",J24," <BR> Chip Select Group: ",K24," <BR> GPIO Port (Pin) Name: ",L24," <BR> Schematic Sheet of Interest: ",C24," <BR> Reference Designators of Interest: ", CONCATENATE(D24,", ",E24),IF(I24<>"",CONCATENATE(" <BR> Note: ",I24),"")) -> //* 0 = Binary group (4-bits) not active <BR> 1 = Binary group (4-bits) active <BR> Description: Output Level Gain Knob bit 3 <BR> I/O: Input (Active High) <BR> Chip Select Group: CS_A <BR> GPIO Port (Pin) Name: P13 <BR> Schematic Sheet of Interest: Front Panel, SPI GPIO input sheet <BR> Reference Designators of Interest: SW4, <BR> Note: Twelve positions is represented by these four bits (Output Level Knob[3:0]) with zero base reference from 0 to 11 in binary count | C24: Front Panel, SPI GPIO input sheet | D24: SW4 | F24: Binary group (4-bits) not active | G24: Binary group (4-bits) active | H24: Output Level Gain Knob bit 3 | I24: Twelve positions is represented by these four bits (Output Level Knob[3:0]) with zero base reference from 0 to 11 in binary count | J24: =VLOOKUP(LEFT(TRIM(A24),1),$U$2:$V$5,2,FALSE) -> Input (Active High) | K24: CS_A | L24: P13
A25: pFRAC_0P5DB :1, | B25: =CONCATENATE("//* 0 = ",F25," <BR> 1 = ",G25," <BR> Description: ",H25," <BR> I/O: ",J25," <BR> Chip Select Group: ",K25," <BR> GPIO Port (Pin) Name: ",L25," <BR> Schematic Sheet of Interest: ",C25," <BR> Reference Designators of Interest: ", CONCATENATE(D25,", ",E25),IF(I25<>"",CONCATENATE(" <BR> Note: ",I25),"")) -> //* 0 = Output level fractional gain/attenuation 0.5dB <BR> 1 = Output level fractional gain/attenuation not set for 0.5dB <BR> Description: Output Level Fractional gain/attenuation 0.5dB <BR> I/O: Input (Active Low) <BR> Chip Select Group: CS_A <BR> GPIO Port (Pin) Name: P14 <BR> Schematic Sheet of Interest: Front Panel, SPI GPIO input sheet <BR> Reference Designators of Interest: S2, <BR> Note: 0.25dB is center off on this switch and is calculated when neither 0.5dB or 0dB are engaged | C25: Front Panel, SPI GPIO input sheet | D25: S2 | F25: Output level fractional gain/attenuation 0.5dB | G25: Output level fractional gain/attenuation not set for 0.5dB | H25: Output Level Fractional gain/attenuation 0.5dB | I25: 0.25dB is center off on this switch and is calculated when neither 0.5dB or 0dB are engaged | J25: =VLOOKUP(LEFT(TRIM(A25),1),$U$2:$V$5,2,FALSE) -> Input (Active Low) | K25: CS_A | L25: P14
A26: pFRAC_0DB :1; | B26: =CONCATENATE("//* 0 = ",F26," <BR> 1 = ",G26," <BR> Description: ",H26," <BR> I/O: ",J26," <BR> Chip Select Group: ",K26," <BR> GPIO Port (Pin) Name: ",L26," <BR> Schematic Sheet of Interest: ",C26," <BR> Reference Designators of Interest: ", CONCATENATE(D26,", ",E26),IF(I26<>"",CONCATENATE(" <BR> Note: ",I26),"")) -> //* 0 = Output level fractional gain/attenuation 0dB <BR> 1 = Output level fractional gain/attenuation not set for 0dB <BR> Description: Output Level Fractional gain/attenuation 0dB <BR> I/O: Input (Active Low) <BR> Chip Select Group: CS_A <BR> GPIO Port (Pin) Name: P15 <BR> Schematic Sheet of Interest: Front Panel, SPI GPIO input sheet <BR> Reference Designators of Interest: S2, <BR> Note: 0.25dB is center off on this switch and is calculated when neither 0.5dB or 0dB are engaged | C26: Front Panel, SPI GPIO input sheet | D26: S2 | F26: Output level fractional gain/attenuation 0dB | G26: Output level fractional gain/attenuation not set for 0dB | H26: Output Level Fractional gain/attenuation 0dB | I26: 0.25dB is center off on this switch and is calculated when neither 0.5dB or 0dB are engaged | J26: =VLOOKUP(LEFT(TRIM(A26),1),$U$2:$V$5,2,FALSE) -> Input (Active Low) | K26: CS_A | L26: P15
A29: #define OUTLEVEL_BYTE_GROUP 2
A30: uchar
A31: dOUTLEVEL_0_RANGE :1, | B31: =CONCATENATE("//* 0 = ",F31," <BR> 1 = ",G31," <BR> Description: ",H31," <BR> I/O: ",J31," <BR> Chip Select Group: ",K31," <BR> GPIO Port (Pin) Name: ",L31," <BR> Schematic Sheet of Interest: ",C31," <BR> Reference Designators of Interest: ", CONCATENATE(D31,", ",E31),IF(I31<>"",CONCATENATE(" <BR> Note: ",I31),"")) -> //* 0 = Relay not engaged, Odd dB values are selected <BR> 1 = Relay Engaged, Even dB levels selected <BR> Description: Seven relay ladder range (even or odd gains/attenuations): Output Level K0 (Range) even/odd dB selection <BR> I/O: Output (Active High) <BR> Chip Select Group: CS_B <BR> GPIO Port (Pin) Name: P0 <BR> Schematic Sheet of Interest: Output Level <BR> Reference Designators of Interest: K13, K26 | C31: Output Level | D31: K13 | E31: K26 | F31: Relay not engaged, Odd dB values are selected | G31: Relay Engaged, Even dB levels selected | H31: Seven relay ladder range (even or odd gains/attenuations): Output Level K0 (Range) even/odd dB selection | J31: =VLOOKUP(LEFT(TRIM(A31),1),$U$2:$V$5,2,FALSE) -> Output (Active High) | K31: CS_B | L31: P0
A32: dOUTLEVEL_1 :1, | B32: =CONCATENATE("//* 0 = ",F32," <BR> 1 = ",G32," <BR> Description: ",H32," <BR> I/O: ",J32," <BR> Chip Select Group: ",K32," <BR> GPIO Port (Pin) Name: ",L32," <BR> Schematic Sheet of Interest: ",C32," <BR> Reference Designators of Interest: ", CONCATENATE(D32,", ",E32),IF(I32<>"",CONCATENATE(" <BR> Note: ",I32),"")) -> //* 0 = Relay not engaged, 0dB or 1dB depending upon Range Relay (K0 RANGE) for even or odd dB level selection <BR> 1 = Relay engaged, 0dB or 1dB not selected <BR> Description: Seven relay ladder, relay 1 <BR> I/O: Output (Active High) <BR> Chip Select Group: CS_B <BR> GPIO Port (Pin) Name: P1 <BR> Schematic Sheet of Interest: Output Level <BR> Reference Designators of Interest: K19, K32 <BR> Note: Relay has highest wired priority when setting gain/attenuation. <BR> Relay is opposite polarity than other relays in this ladder to account for relay priority when brown-out or power down (this relay takes precedence to drop gain closer to 0dB during power down or brown-out; mechanically / electrically rather than "softwarely") | C32: Output Level | D32: K19 | E32: K32 | F32: Relay not engaged, 0dB or 1dB depending upon Range Relay (K0 RANGE) for even or odd dB level selection | G32: Relay engaged, 0dB or 1dB not selected | H32: Seven relay ladder, relay 1 | I32: Relay has highest wired priority when setting gain/attenuation. <BR> Relay is opposite polarity than other relays in this ladder to account for relay priority when brown-out or power down (this relay takes precedence to drop gain closer to 0dB during power down or brown-out; mechanically / electrically rather than "softwarely") | J32: =VLOOKUP(LEFT(TRIM(A32),1),$U$2:$V$5,2,FALSE) -> Output (Active High) | K32: CS_B | L32: P1
A33: dOUTLEVEL_2 :1, | B33: =CONCATENATE("//* 0 = ",F33," <BR> 1 = ",G33," <BR> Description: ",H33," <BR> I/O: ",J33," <BR> Chip Select Group: ",K33," <BR> GPIO Port (Pin) Name: ",L33," <BR> Schematic Sheet of Interest: ",C33," <BR> Reference Designators of Interest: ", CONCATENATE(D33,", ",E33),IF(I33<>"",CONCATENATE(" <BR> Note: ",I33),"")) -> //* 0 = Relay not engaged, 2dB or 3dB not selected <BR> 1 = Relay engaged, 2dB or 3dB depending upon Range relay (K0 RANGE) for even or odd dB level selection <BR> Description: Seven relay ladder, relay 2 <BR> I/O: Output (Active High) <BR> Chip Select Group: CS_B <BR> GPIO Port (Pin) Name: P2 <BR> Schematic Sheet of Interest: Output Level <BR> Reference Designators of Interest: K18, K31 | C33: Output Level | D33: K18 | E33: K31 | F33: Relay not engaged, 2dB or 3dB not selected | G33: Relay engaged, 2dB or 3dB depending upon Range relay (K0 RANGE) for even or odd dB level selection | H33: Seven relay ladder, relay 2 | J33: =VLOOKUP(LEFT(TRIM(A33),1),$U$2:$V$5,2,FALSE) -> Output (Active High) | K33: CS_B | L33: P2
A34: dOUTLEVEL_3 :1, | B34: =CONCATENATE("//* 0 = ",F34," <BR> 1 = ",G34," <BR> Description: ",H34," <BR> I/O: ",J34," <BR> Chip Select Group: ",K34," <BR> GPIO Port (Pin) Name: ",L34," <BR> Schematic Sheet of Interest: ",C34," <BR> Reference Designators of Interest: ", CONCATENATE(D34,", ",E34),IF(I34<>"",CONCATENATE(" <BR> Note: ",I34),"")) -> //* 0 = Relay not engaged, 4dB or 5dB not selected <BR> 1 = Relay engaged, 4dB or 5dB depending upon Range relay (K0 RANGE) for even or odd dB level selection <BR> Description: Seven relay ladder, relay 3 <BR> I/O: Output (Active High) <BR> Chip Select Group: CS_B <BR> GPIO Port (Pin) Name: P3 <BR> Schematic Sheet of Interest: Output Level <BR> Reference Designators of Interest: K17, K30 | C34: Output Level | D34: K17 | E34: K30 | F34: Relay not engaged, 4dB or 5dB not selected | G34: Relay engaged, 4dB or 5dB depending upon Range relay (K0 RANGE) for even or odd dB level selection | H34: Seven relay ladder, relay 3 | J34: =VLOOKUP(LEFT(TRIM(A34),1),$U$2:$V$5,2,FALSE) -> Output (Active High) | K34: CS_B | L34: P3
A35: dOUTLEVEL_4 :1, | B35: =CONCATENATE("//* 0 = ",F35," <BR> 1 = ",G35," <BR> Description: ",H35," <BR> I/O: ",J35," <BR> Chip Select Group: ",K35," <BR> GPIO Port (Pin) Name: ",L35," <BR> Schematic Sheet of Interest: ",C35," <BR> Reference Designators of Interest: ", CONCATENATE(D35,", ",E35),IF(I35<>"",CONCATENATE(" <BR> Note: ",I35),"")) -> //* 0 = Relay not engaged, 6dB or 7dB not selected <BR> 1 = Relay engaged, 6dB or 7dB depending upon Range relay (K0 RANGE) for even or odd dB level selection <BR> Description: Seven relay ladder, relay 4 <BR> I/O: Output (Active High) <BR> Chip Select Group: CS_B <BR> GPIO Port (Pin) Name: P4 <BR> Schematic Sheet of Interest: Output Level <BR> Reference Designators of Interest: K16, K29 | C35: Output Level | D35: K16 | E35: K29 | F35: Relay not engaged, 6dB or 7dB not selected | G35: Relay engaged, 6dB or 7dB depending upon Range relay (K0 RANGE) for even or odd dB level selection | H35: Seven relay ladder, relay 4 | J35: =VLOOKUP(LEFT(TRIM(A35),1),$U$2:$V$5,2,FALSE) -> Output (Active High) | K35: CS_B | L35: P4
A36: dOUTLEVEL_5 :1, | B36: =CONCATENATE("//* 0 = ",F36," <BR> 1 = ",G36," <BR> Description: ",H36," <BR> I/O: ",J36," <BR> Chip Select Group: ",K36," <BR> GPIO Port (Pin) Name: ",L36," <BR> Schematic Sheet of Interest: ",C36," <BR> Reference Designators of Interest: ", CONCATENATE(D36,", ",E36),IF(I36<>"",CONCATENATE(" <BR> Note: ",I36),"")) -> //* 0 = Relay not engaged, 8dB or 9dB not selected <BR> 1 = Relay engaged, 8dB or 9dB depending upon Range relay (K0 RANGE) for even or odd dB level selection <BR> Description: Seven relay ladder, relay 5 <BR> I/O: Output (Active High) <BR> Chip Select Group: CS_B <BR> GPIO Port (Pin) Name: P5 <BR> Schematic Sheet of Interest: Output Level <BR> Reference Designators of Interest: K15, K28 | C36: Output Level | D36: K15 | E36: K28 | F36: Relay not engaged, 8dB or 9dB not selected | G36: Relay engaged, 8dB or 9dB depending upon Range relay (K0 RANGE) for even or odd dB level selection | H36: Seven relay ladder, relay 5 | J36: =VLOOKUP(LEFT(TRIM(A36),1),$U$2:$V$5,2,FALSE) -> Output (Active High) | K36: CS_B | L36: P5
A37: dOUTLEVEL_6 :1, | B37: =CONCATENATE("//* 0 = ",F37," <BR> 1 = ",G37," <BR> Description: ",H37," <BR> I/O: ",J37," <BR> Chip Select Group: ",K37," <BR> GPIO Port (Pin) Name: ",L37," <BR> Schematic Sheet of Interest: ",C37," <BR> Reference Designators of Interest: ", CONCATENATE(D37,", ",E37),IF(I37<>"",CONCATENATE(" <BR> Note: ",I37),"")) -> //* 0 = Relay not engaged, 10dB or 11dB not selected <BR> 1 = Relay engaged, 10dB or 11dB depending upon Range relay (K0 RANGE) for even or odd dB level selection <BR> Description: Seven relay ladder, relay 6 <BR> I/O: Output (Active High) <BR> Chip Select Group: CS_B <BR> GPIO Port (Pin) Name: P6 <BR> Schematic Sheet of Interest: Output Level <BR> Reference Designators of Interest: K14, K27 <BR> Note: Relay has least wired priority | C37: Output Level | D37: K14 | E37: K27 | F37: Relay not engaged, 10dB or 11dB not selected | G37: Relay engaged, 10dB or 11dB depending upon Range relay (K0 RANGE) for even or odd dB level selection | H37: Seven relay ladder, relay 6 | I37: Relay has least wired priority | J37: =VLOOKUP(LEFT(TRIM(A37),1),$U$2:$V$5,2,FALSE) -> Output (Active High) | K37: CS_B | L37: P6
A38: dOUTLEVEL_0_25 :1; | B38: =CONCATENATE("//* 0 = ",F38," <BR> 1 = ",G38," <BR> Description: ",H38," <BR> I/O: ",J38," <BR> Chip Select Group: ",K38," <BR> GPIO Port (Pin) Name: ",L38," <BR> Schematic Sheet of Interest: ",C38," <BR> Reference Designators of Interest: ", CONCATENATE(D38,", ",E38),IF(I38<>"",CONCATENATE(" <BR> Note: ",I38),"")) -> //* 0 = Relay not engaged, 0.25 fractional gain/attenuation not selected <BR> 1 = Gain or attenuated by 0.25dB depending upon boost or cut status <BR> Description: Fractional gain relay 0.25dB <BR> I/O: Output (Active High) <BR> Chip Select Group: CS_B <BR> GPIO Port (Pin) Name: P7 <BR> Schematic Sheet of Interest: Output Level <BR> Reference Designators of Interest: K20, K33 | C38: Output Level | D38: K20 | E38: K33 | F38: Relay not engaged, 0.25 fractional gain/attenuation not selected | G38: Gain or attenuated by 0.25dB depending upon boost or cut status | H38: Fractional gain relay 0.25dB | J38: =VLOOKUP(LEFT(TRIM(A38),1),$U$2:$V$5,2,FALSE) -> Output (Active High) | K38: CS_B | L38: P7
A40: #define XFORMER_BYTE_GROUP 3
A41: uchar
A42: dOUTLEVEL_0_5 :1, | B42: =CONCATENATE("//* 0 = ",F42," <BR> 1 = ",G42," <BR> Description: ",H42," <BR> I/O: ",J42," <BR> Chip Select Group: ",K42," <BR> GPIO Port (Pin) Name: ",L42," <BR> Schematic Sheet of Interest: ",C42," <BR> Reference Designators of Interest: ", CONCATENATE(D42,", ",E42),IF(I42<>"",CONCATENATE(" <BR> Note: ",I42),"")) -> //* 0 = Relay not engaged, 0.5 fractional gain/attenuation not selected <BR> 1 = Relay engaged, gain or attenuate by 0.5dB depending upon boost or cut status <BR> Description: Fractional gain relay 0.5dB <BR> I/O: Output (Active High) <BR> Chip Select Group: CS_B <BR> GPIO Port (Pin) Name: P8 <BR> Schematic Sheet of Interest: Output Level <BR> Reference Designators of Interest: K21, K34 | C42: Output Level | D42: K21 | E42: K34 | F42: Relay not engaged, 0.5 fractional gain/attenuation not selected | G42: Relay engaged, gain or attenuate by 0.5dB depending upon boost or cut status | H42: Fractional gain relay 0.5dB | J42: =VLOOKUP(LEFT(TRIM(A42),1),$U$2:$V$5,2,FALSE) -> Output (Active High) | K42: CS_B | L42: P8
A43: dOUTLEVEL_BOOST :1, | B43: =CONCATENATE("//* 0 = ",F43," <BR> 1 = ",G43," <BR> Description: ",H43," <BR> I/O: ",J43," <BR> Chip Select Group: ",K43," <BR> GPIO Port (Pin) Name: ",L43," <BR> Schematic Sheet of Interest: ",C43," <BR> Reference Designators of Interest: ", CONCATENATE(D43,", ",E43),IF(I43<>"",CONCATENATE(" <BR> Note: ",I43),"")) -> //* 0 = Relays not engaged, Output Level in CUT mode <BR> 1 = Relays engaged, Output Level in BOOST mode <BR> Description: Output Level boost or cut mode relay <BR> I/O: Output (Active High) <BR> Chip Select Group: CS_B <BR> GPIO Port (Pin) Name: P9 <BR> Schematic Sheet of Interest: Output Level <BR> Reference Designators of Interest: K11, K12, K24, and K25 <BR> Note: This swaps T-network resistors to be either on the gain side of the opamp or on the attenuation side of the opamp. Fractional T-network resistors are always on the opposite side of the main whole dB T-network resistors; when attenuating by whole dB resistor values, fractional resistor values are gain values and vice versa. | C43: Output Level | D43: K11, K12 | E43: K24, and K25 | F43: Relays not engaged, Output Level in CUT mode | G43: Relays engaged, Output Level in BOOST mode | H43: Output Level boost or cut mode relay | I43: This swaps T-network resistors to be either on the gain side of the opamp or on the attenuation side of the opamp. Fractional T-network resistors are always on the opposite side of the main whole dB T-network resistors; when attenuating by whole dB resistor values, fractional resistor values are gain values and vice versa. | J43: =VLOOKUP(LEFT(TRIM(A43),1),$U$2:$V$5,2,FALSE) -> Output (Active High) | K43: CS_B | L43: P9
A44: dXFORMER_SEC :1, | B44: =CONCATENATE("//* 0 = ",F44," <BR> 1 = ",G44," <BR> Description: ",H44," <BR> I/O: ",J44," <BR> Chip Select Group: ",K44," <BR> GPIO Port (Pin) Name: ",L44," <BR> Schematic Sheet of Interest: ",C44," <BR> Reference Designators of Interest: ", CONCATENATE(D44,", ",E44),IF(I44<>"",CONCATENATE(" <BR> Note: ",I44),"")) -> //* 0 = Relay not engaged, Transformer not in circuit <BR> 1 = <BR> Description: <BR> I/O: Output (Active High) <BR> Chip Select Group: CS_B <BR> GPIO Port (Pin) Name: P10 <BR> Schematic Sheet of Interest: Transformer <BR> Reference Designators of Interest: K53, K57 | C44: Transformer | D44: K53 | E44: K57 | F44: Relay not engaged, Transformer not in circuit | J44: =VLOOKUP(LEFT(TRIM(A44),1),$U$2:$V$5,2,FALSE) -> Output (Active High) | K44: CS_B | L44: P10
A45: dXFORMER_MODE2 :1, | B45: =CONCATENATE("//* 0 = ",F45," <BR> 1 = ",G45," <BR> Description: ",H45," <BR> I/O: ",J45," <BR> Chip Select Group: ",K45," <BR> GPIO Port (Pin) Name: ",L45," <BR> Schematic Sheet of Interest: ",C45," <BR> Reference Designators of Interest: ", CONCATENATE(D45,", ",E45),IF(I45<>"",CONCATENATE(" <BR> Note: ",I45),"")) -> //* 0 = Relay not engaged, Mode 1 (if Transformer is "in") <BR> 1 = <BR> Description: <BR> I/O: Output (Active High) <BR> Chip Select Group: CS_B <BR> GPIO Port (Pin) Name: P11 <BR> Schematic Sheet of Interest: Transformer <BR> Reference Designators of Interest: K54, K58 | C45: Transformer | D45: K54 | E45: K58 | F45: Relay not engaged, Mode 1 (if Transformer is "in") | J45: =VLOOKUP(LEFT(TRIM(A45),1),$U$2:$V$5,2,FALSE) -> Output (Active High) | K45: CS_B | L45: P11
...

Sheet Sheet2
A2: uchar pCUT; | D2: =CONCATENATE("//* Debounce bit counter for: ",Sheet1!H2) -> //* Debounce bit counter for: Gain Mode Switch (Cut), Front Panel
A3: uchar pBOOST; | D3: =CONCATENATE("//* Debounce bit counter for: ",Sheet1!H3) -> //* Debounce bit counter for: Gain Mode Switch (Boost), Front Panel
A4: uchar bLOADING_A0; | D4: =CONCATENATE("//* Debounce bit counter for: ",Sheet1!H4) -> //* Debounce bit counter for: Loading Knob bit 0
A5: uchar bLOADING_A1; | D5: =CONCATENATE("//* Debounce bit counter for: ",Sheet1!H5) -> //* Debounce bit counter for: Loading Knob bit 1
A6: uchar bLOADING_A2; | D6: =CONCATENATE("//* Debounce bit counter for: ",Sheet1!H6) -> //* Debounce bit counter for: Loading Knob bit 2
A7: uchar bLOADING_A3; | D7: =CONCATENATE("//* Debounce bit counter for: ",Sheet1!H7) -> //* Debounce bit counter for: Loading Knob bit 3
A8: uchar pXFORMER_A0; | D8: =CONCATENATE("//* Debounce bit counter for: ",Sheet1!H8) -> //* Debounce bit counter for: Transformer Mode Knob bit 0
A9: uchar pXFORMER_A1; | D9: =CONCATENATE("//* Debounce bit counter for: ",Sheet1!H9) -> //* Debounce bit counter for: Transformer Mode Knob bit 1
A11: uchar pFILTER_A0; | D11: =CONCATENATE("//* Debounce bit counter for: ",Sheet1!H19) -> //* Debounce bit counter for: Filter Mode Knob bit 0
A12: uchar pFILTER_A1; | D12: =CONCATENATE("//* Debounce bit counter for: ",Sheet1!H20) -> //* Debounce bit counter for: Filter Mode Knob bit 1
A13: uchar bOUTLEVEL_A0; | D13: =CONCATENATE("//* Debounce bit counter for: ",Sheet1!H21) -> //* Debounce bit counter for: Output Level Gain Knob bit 0
A14: uchar bOUTLEVEL_A1; | D14: =CONCATENATE("//* Debounce bit counter for: ",Sheet1!H22) -> //* Debounce bit counter for: Output Level Gain Knob bit 1
A15: uchar bOUTLEVEL_A2; | D15: =CONCATENATE("//* Debounce bit counter for: ",Sheet1!H23) -> //* Debounce bit counter for: Output Level Gain Knob bit 2
A16: uchar bOUTLEVEL_A3; | D16: =CONCATENATE("//* Debounce bit counter for: ",Sheet1!H24) -> //* Debounce bit counter for: Output Level Gain Knob bit 3
A17: uchar pFRAC_0P5DB; | D17: =CONCATENATE("//* Debounce bit counter for: ",Sheet1!H25) -> //* Debounce bit counter for: Output Level Fractional gain/attenuation 0.5dB
A18: uchar pFRAC_0DB; | D18: =CONCATENATE("//* Debounce bit counter for: ",Sheet1!H26) -> //* Debounce bit counter for: Output Level Fractional gain/attenuation 0dB
A20: uchar pFB_CLEAN; | D20: =CONCATENATE("//* Debounce bit counter for: ",Sheet1!H48) -> //* Debounce bit counter for: Front Panel input for Tube Opamp mode (feedback or feedforward mode of operation, e.g., clean versus bloom modes)
A21: uchar pMODE; | D21: =CONCATENATE("//* Debounce bit counter for: ",Sheet1!H49) -> //* Debounce bit counter for: Front Panel input for Mode momentary toggle position (far right) to operate overall System mode (open, pre, post, link, LED brightness control)
A22: uchar bLINEAMP_ENGAGE; | D22: =CONCATENATE("//* Debounce bit counter for: ",Sheet1!H71) -> //* Debounce bit counter for: Input to sense if bypass switch is active

Sheet Sheet3
